Workbook

Sheet Menu
D2: SINAPI
D3: Sistema Nacional de Pesquisa de Custos e Índices da Construção Civil
B5: =HYPERLINK("#Busca!$B$8","Pesquisa") -> 0 | D5: Permite a pesquisa de insumos ou composições, por termos não consecutivos, com filtro "contém" e "não contém"
B7: =HYPERLINK("#'ISD'!$F$11","Insumos Não Desonerado") -> 0 | D7: Relatório de preços de insumos sem desoneração para as 27 UF. Inclui link para as fichas de especificação técnica dos insumos.
B9: =HYPERLINK("#'ICD'!$F$11","Insumos Desonerado") -> 0 | D9: Relatório de preços de insumos com desoneração para as 27 UF. Inclui link para as fichas de especificação técnica dos insumos.
B11: =HYPERLINK("#'ISE'!$F$11","Insumos Sem Encargos") -> 0 | D11: Relatório de preços de insumos sem encargos sociais para as 27 UF. Inclui link para as fichas de especificação técnica dos insumos.
B13: =HYPERLINK("#'CSD'!$E$11","Composições Não Desonerado") -> 0 | D13: Relatório de custos de composição sem desoneração para as 27 UF. Inclui links para os cadernos técnicos, links para o analítico da composição, composições com custo e sem custo.
B15: =HYPERLINK("#'CCD'!$E$11","Composições Desonerado") -> 0 | D15: Relatório de custos de composição com desoneração para as 27 UF. Inclui links para os cadernos técnicos, links para o analítico da composição, composições com custo e sem custo.
B17: =HYPERLINK("#'CSE'!$E$11","Composições Sem Encargos") -> 0 | D17: Relatório de custos de composição sem encargos sociais para as 27 UF. Inclui links para os cadernos técnicos, links para o analítico da composição, composições com custo e sem custo.
B19: =HYPERLINK("#Analítico!$A$11","Analítico") -> 0 | D19: Relatório analítico das composições.
B21: =HYPERLINK("#'Analítico com Custo'!$C$8","Analítico com Custo") -> 0 | D21: Permite a consulta do analítico com custos para uma composição, UF e regime de desoneração selecionados.

Sheet Busca
A1: SINAPI - Sistema Nacional de Pesquisa de Custos e Índices da Construção Civil
A2: PESQUISA POR TERMOS NAS DESCRIÇÕES
B4: Instruções:
B5: Preencher a pesquisa com palavras separadas por espaço. Acentuação das palavras afeta a pesquisa. Ordem das palavras ou maiúscula/minúscula não afeta a pesquisa. O campo "Pesquisar em" deve ser preenchido com "insumos" ou "composições". O campo "Contém" é obrigatório. Funciona somente em versões do Excel que tenham disponíveis as fórmulas FILTRO, CLASSIFICAR, DIVIDIRTEXTO, BYROW e LAMBDA
A7: Pesquisar em: | B7: composições
A8: Contém*: | B8: paviment execução asf
A9: Não Contém:
B10: =COUNTIF($B$12:$B$15000,"<>")&" RESULTADOS" -> 0
A11: =IF($B$7="insumos","Cód. Insumo",IF($B$7="composições","Cód. Composição","")) -> 0 | B11: Descrição | C11: Unidade
A12: {=IF($B$7="composições",_xlfn._xlws.SORT(_xlfn._xlws.FILTER('CSD'!B11:D15000,_xlfn.BYROW('CSD'!C11:C15000,_xlfn.LAMBDA(_xlpm.linha,AND(AND(ISNUMBER(SEARCH(_xlfn.TEXTSPLIT(($B$8)," "),_xlpm.linha))),NOT(OR(ISNUMBER(SEARCH(_xlfn.TEXTSPLIT(($B$9)," "),_xlpm.linha)))))))),2,1),IF($B$7="insumos",_xlfn._xlws.SORT(_xlfn._xlws.FILTER('ISD'!B11:D15000,_xlfn.BYROW('ISD'!C11:C15000,_xlfn.LAMBDA(_xlpm.linha,AND(AND(ISNUMBER(SEARCH(_xlfn.TEXTSPLIT(($B$8)," "),_xlpm.linha))),NOT(OR(ISNUMBER(SEARCH(_xlfn.TEXTSPLIT(($B$9)," "),_xlpm.linha)))))))),2,1),""))} -> 0

Sheet ISD
A1: SINAPI - Sistema Nacional de Pesquisa de Custos e Índices da Construção Civil
A2: RELATÓRIO DE PREÇOS DE INSUMOS - ENGARGOS SOCIAIS SEM DESONERAÇÃO
A3: Mês de Referência: | B3: 01/2026 | E3: Encargos sociais sobre a mão de obra:
A4: Data de emissão: | B4: 23/03/2026 | E4: (SEM DESONERAÇÃO) | F4: AC | G4: AL | H4: AM | I4: AP | J4: BA | K4: CE | L4: DF | M4: ES | N4: GO | O4: MA | P4: MG | Q4: MS | R4: MT | S4: PA | T4: PB | U4: PE | V4: PI | W4: PR | X4: RJ | Y4: RN | Z4: RO | AA4: RR | AB4: RS | AC4: SC | AD4: SE | AE4: SP | AF4: TO
E5: Localidade | F5: RIO BRANCO | G5: MACEIO | H5: MANAUS | I5: MACAPA | J5: SALVADOR | K5: FORTALEZA | L5: BRASILIA | M5: VITORIA | N5: GOIANIA | O5: SAO LUIS | P5: BELO HORIZONTE | Q5: CAMPO GRANDE | R5: CUIABA | S5: BELEM | T5: JOAO PESSOA | U5: RECIFE | V5: TERESINA | W5: CURITIBA | X5: RIO DE JANEIRO | Y5: NATAL | Z5: PORTO VELHO | AA5: BOA VISTA | AB5: PORTO ALEGRE | AC5: FLORIANOPOLIS | AD5: ARACAJU | AE5: SAO PAULO | AF5: PALMAS
A6: Origem de preço: | B6: C = COLETADO | C6: CR = COEFICIENTE DE REPRESENTATIVIDADE | E6: Horista | F6: 1.1261 | G6: 1.1612 | H6: 1.1416 | I6: 1.1518 | J6: 1.1773 | K6: 1.1561 | L6: 1.1008 | M6: 1.183 | N6: 1.0772 | O6: 1.1411 | P6: 1.1623 | Q6: 1.1571 | R6: 1.0533 | S6: 1.1942 | T6: 1.1819 | U6: 1.1463 | V6: 1.1378 | W6: 1.1628 | X6: 1.1249 | Y6: 1.1683 | Z6: 1.1571 | AA6: 1.1479 | AB6: 1.1195 | AC6: 1.1447 | AD6: 1.1151 | AE6: 1.1501 | AF6: 1.1523
A7: Preço em branco para determinado estado significa que não houve coleta mínima de preços no mês de referência | E7: Mensalista | F7: 0.6903 | G7: 0.7125 | H7: 0.708 | I7: 0.7006 | J7: 0.7285 | K7: 0.7246 | L7: 0.6994 | M7: 0.7385 | N7: 0.6928 | O7: 0.713 | P7: 0.7383 | Q7: 0.7157 | R7: 0.6783 | S7: 0.727 | T7: 0.7266 | U7: 0.7067 | V7: 0.7159 | W7: 0.7242 | X7: 0.6966 | Y7: 0.7229 | Z7: 0.7065 | AA7: 0.7035 | AB7: 0.6929 | AC7: 0.7103 | AD7: 0.6972 | AE7: 0.7118 | AF7: 0.7198
A9: Acessar Fichas de Especificação Técnico dos Insumos | E9: Preços Medianos (R$):
A10: Classificação | B10: Código do Insumo | C10: Descrição do Insumo | D10: Unidade | E10: Origem de Preço | F10: AC | G10: AL | H10: AM | I10: AP | J10: BA | K10: CE | L10: DF | M10: ES | N10: GO | O10: MA | P10: MG | Q10: MS | R10: MT | S10: PA | T10: PB | U10: PE | V10: PI | W10: PR | X10: RJ | Y10: RN | Z10: RO | AA10: RR | AB10: RS | AC10: SC | AD10: SE | AE10: SP | AF10: TO
A57: MATERIAL | B57: 1 | C57: ACETILENO - RECARGA DE GAS PARA CILINDRO (NAO INCLUI TROCA/MANUTENCAO DO CILINDRO) | D57: KG | E57: C | G57: 133.33 | J57: 157.78 | K57: 101.13 | M57: 105 | N57: 97.77 | P57: 80 | Q57: 100 | R57: 119.64 | W57: 140 | AB57: 110.5 | AE57: 110
A184: ENCARGOS COMPLEMENTARES | B184: 37370 | C184: ALIMENTACAO - HORISTA (COLETADO CAIXA - ENCARGOS COMPLEMENTARES) | D184: H | E184: C | F184: 3.4 | G184: 2.68 | H184: 5.58 | I184: 0.66 | J184: 5 | K184: 4.15 | L184: 4.29 | M184: 7.63 | N184: 3.61 | O184: 2.2 | P184: 2.41 | Q184: 1.73 | R184: 2.9 | S184: 5.15 | T184: 1.82 | U184: 3.06 | V184: 2.49 | W184: 5.96 | X184: 4.78 | Y184: 4.93 | Z184: 3.76 | AA184: 3.52 | AB184: 1.82 | AC184: 0.01 | AD184: 2.96 | AE184: 4.48 | AF184: 2.39
A317: MATERIAL | B317: 34353 | C317: ARGAMASSA COLANTE AC II | D317: KG | E317: CR | F317: 2.42 | G317: 1.86 | H317: 2.38 | I317: 2.1 | J317: 1.58 | K317: 2.17 | L317: 1.19 | M317: 1.35 | N317: 1.49 | O317: 1.91 | P317: 1.26 | Q317: 1.76 | R317: 2.32 | S317: 1.67 | T317: 1.49 | U317: 1.86 | V317: 1.35 | W317: 1.41 | X317: 1.3 | Y317: 1.82 | Z317: 1.99 | AA317: 3.09 | AB317: 1.49 | AC317: 1.3 | AD317: 1.73 | AE317: 1.49 | AF317: 1.39
A320: MATERIAL | B320: 371 | C320: ARGAMASSA INDUSTRIALIZADA MULTIUSO, PARA REVESTIMENTO INTERNO E EXTERNO E ASSENTAMENTO DE BLOCOS DIVERSOS | D320: KG | E320: CR | F320: 1.42 | G320: 1.09 | H320: 1.39 | I320: 1.23 | J320: 0.92 | K320: 1.27 | L320: 0.69 | M320: 0.79 | N320: 0.87 | O320: 1.12 | P320: 0.74 | Q320: 1.03 | R320: 1.36 | S320: 0.98 | T320: 0.87 | U320: 1.09 | V320: 0.79 | W320: 0.83 | X320: 0.76 | Y320: 1.07 | Z320: 1.16 | AA320: 1.81 | AB320: 0.87 | AC320: 0.76 | AD320: 1.01 | AE320: 0.87 | AF320: 0.81
A1932: ENCARGOS COMPLEMENTARES | B1932: 43489 | C1932: EPI - FAMILIA PEDREIRO - HORISTA (ENCARGOS COMPLEMENTARES - COLETADO CAIXA) | D1932: H | E1932: C | F1932: 1.46 | G1932: 1.45 | H1932: 1.46 | I1932: 1.74 | J1932: 1.41 | K1932: 1.5 | L1932: 1.26 | M1932: 1.28 | N1932: 1.13 | O1932: 1.32 | P1932: 1.43 | Q1932: 1.43 | R1932: 1.72 | S1932: 1.76 | T1932: 1.68 | U1932: 1.47 | V1932: 1.81 | W1932: 1.64 | X1932: 1.71 | Y1932: 1.25 | Z1932: 1.56 | AA1932: 1.85 | AB1932: 1.62 | AC1932: 1.55 | AD1932: 1.28 | AE1932: 1.47 | AF1932: 1.6
A1936: ENCARGOS COMPLEMENTARES | B1936: 43491 | C1936: EPI - FAMILIA SERVENTE - HORISTA (ENCARGOS COMPLEMENTARES - COLETADO CAIXA) | D1936: H | E1936: C | F1936: 1.53 | G1936: 1.52 | H1936: 1.53 | I1936: 1.82 | J1936: 1.48 | K1936: 1.57 | L1936: 1.32 | M1936: 1.34 | N1936: 1.18 | O1936: 1.38 | P1936: 1.5 | Q1936: 1.5 | R1936: 1.8 | S1936: 1.85 | T1936: 1.75 | U1936: 1.54 | V1936: 1.89 | W1936: 1.71 | X1936: 1.79 | Y1936: 1.31 | Z1936: 1.63 | AA1936: 1.94 | AB1936: 1.7 | AC1936: 1.62 | AD1936: 1.34 | AE1936: 1.54 | AF1936: 1.67
A1993: ENCARGOS COMPLEMENTARES | B1993: 37372 | C1993: EXAMES - HORISTA (COLETADO CAIXA - ENCARGOS COMPLEMENTARES) | D1993: H | E1993: C | F1993: 1.32 | G1993: 1.4 | H1993: 1.29 | I1993: 1.3 | J1993: 1.49 | K1993: 1.48 | L1993: 1.31 | M1993: 1.62 | N1993: 1.58 | O1993: 1.36 | P1993: 1.57 | Q1993: 1.67 | R1993: 1.62 | S1993: 1.51 | T1993: 1.56 | U1993: 1.24 | V1993: 1.42 | W1993: 1.58 | X1993: 1.25 | Y1993: 1.55 | Z1993: 1.52 | AA1993: 1.36 | AB1993: 1.36 | AC1993: 1.65 | AD1993: 1.39 | AE1993: 1.43 | AF1993: 1.59
A2052: ENCARGOS COMPLEMENTARES | B2052: 43465 | C2052: FERRAMENTAS - FAMILIA PEDREIRO - HORISTA (ENCARGOS COMPLEMENTARES - COLETADO CAIXA) | D2052: H | E2052: C | F2052: 0.7 | G2052: 0.6 | H2052: 0.57 | I2052: 0.65 | J2052: 0.59 | K2052: 0.6 | L2052: 0.71 | M2052: 0.68 | N2052: 0.62 | O2052: 0.73 | P2052: 0.8 | Q2052: 0.81 | R2052: 0.74 | S2052: 0.65 | T2052: 0.63 | U2052: 0.6 | V2052: 0.9 | W2052: 0.6 | X2052: 0.64 | Y2052: 0.66 | Z2052: 0.74 | AA2052: 0.63 | AB2052: 0.71 | AC2052: 0.72 | AD2052: 0.61 | AE2052: 0.73 | AF2052: 0.83
A2056: ENCARGOS COMPLEMENTARES | B2056: 43467 | C2056: FERRAMENTAS - FAMILIA SERVENTE - HORISTA (ENCARGOS COMPLEMENTARES - COLETADO CAIXA) | D2056: H | E2056: C | F2056: 0.6 | G2056: 0.48 | H2056: 0.57 | I2056: 0.61 | J2056: 0.47 | K2056: 0.57 | L2056: 0.58 | M2056: 0.57 | N2056: 0.56 | O2056: 0.58 | P2056: 0.67 | Q2056: 0.49 | R2056: 0.6 | S2056: 0.56 | T2056: 0.58 | U2056: 0.5 | V2056: 1 | W2056: 0.42 | X2056: 0.56 | Y2056: 0.62 | Z2056: 0.63 | AA2056: 0.64 | AB2056: 0.57 | AC2056: 0.6 | AD2056: 0.49 | AE2056: 0.57 | AF2056: 0.69
A3133: MATERIAL | B3133: 2 | C3133: OXIGENIO - RECARGA DE GAS PARA CILINDRO (NAO INCLUI TROCA/MANUTENCAO DO CILINDRO) | D3133: M3 | E3133: CR | G3133: 29.22 | J3133: 34.58 | K3133: 22.16 | M3133: 23.01 | N3133: 21.42 | P3133: 17.53 | Q3133: 21.91 | R3133: 26.22 | W3133: 30.68 | AB3133: 24.21 | AE3133: 24.1
A3258: MAO DE OBRA | B3258: 4750 | C3258: PEDREIRO (HORISTA) | D3258: H | E3258: C | F3258: 23.38 | G3258: 20.27 | H3258: 21.67 | I3258: 21.32 | J3258: 24.29 | K3258: 21.86 | L3258: 23.15 | M3258: 22.09 | N3258: 24.01 | O3258: 21.28 | P3258: 25.86 | Q3258: 21.26 | R3258: 22.29 | S3258: 21.92 | T3258: 21.6 | U3258: 22.53 | V3258: 21.8 | W3258: 28.95 | X3258: 30.32 | Y3258: 19.83 | Z3258: 22.99 | AA3258: 25.53 | AB3258: 22.76 | AC3258: 30.56 | AD3258: 20.45 | AE3258: 26.03 | AF3258: 21.3
A3358: MATERIAL | B3358: 36178 | C3358: PISO TATIL / PODOTATIL, LADRILHO HIDRAULICO/CONCRETO, *40 X 40* CM, E= 2,5* CM, PADRAO TATIL ALERTA OU DIRECIONAL, COR NATURAL | D3358: UN | E3358: CR | F3358: 28.02 | G3358: 14.34 | H3358: 22.95 | I3358: 20.85 | J3358: 15.44 | K3358: 14.34 | L3358: 19.44 | M3358: 16.55 | N3358: 17.83 | O3358: 15.44 | P3358: 15.54 | Q3358: 17.29 | R3358: 22.03 | S3358: 15.88 | T3358: 12.8 | U3358: 13.46 | V3358: 13.57 | W3358: 12.62 | X3358: 15.88 | Y3358: 15.56 | Z3358: 21.4 | AA3358: 28.68 | AB3358: 14.17 | AC3358: 12.81 | AD3358: 16.55 | AE3358: 18.3 | AF3358: 20.85
A3730: MATERIAL | B3730: 34357 | C3730: REJUNTE CIMENTICIO, QUALQUER COR | D3730: KG | E3730: CR | F3730: 7.63 | G3730: 5.87 | H3730: 7.51 | I3730: 6.63 | J3730: 4.99 | K3730: 6.87 | L3730: 3.75 | M3730: 4.28 | N3730: 4.69 | O3730: 6.04 | P3730: 3.99 | Q3730: 5.57 | R3730: 7.34 | S3730: 5.28 | T3730: 4.69 | U3730: 5.87 | V3730: 4.28 | W3730: 4.46 | X3730: 4.11 | Y3730: 5.75 | Z3730: 6.28 | AA3730: 9.74 | AB3730: 4.69 | AC3730: 4.11 | AD3730: 5.46 | AE3730: 4.69 | AF3730: 4.4
A3804: ENCARGOS COMPLEMENTARES | B3804: 37373 | C3804: SEGURO - HORISTA (COLETADO CAIXA - ENCARGOS COMPLEMENTARES) | D3804: H | E3804: C | F3804: 0.11 | G3804: 0.11 | H3804: 0.11 | I3804: 0.01 | J3804: 0.11 | K3804: 0.11 | L3804: 0.11 | M3804: 0.11 | N3804: 0.1 | O3804: 0.11 | P3804: 0.11 | Q3804: 0.11 | R3804: 0.1 | S3804: 0.11 | T3804: 0.01 | U3804: 0.11 | V3804: 0.11 | W3804: 0.06 | X3804: 0.11 | Y3804: 0.11 | Z3804: 0.01 | AA3804: 0.01 | AB3804: 0.11 | AC3804: 0.11 | AD3804: 0.11 | AE3804: 0.11 | AF3804: 0.11
A3825: MAO DE OBRA | B3825: 6110 | C3825: SERRALHEIRO (HORISTA) | D3825: H | E3825: CR | F3825: 23.38 | G3825: 22.28 | H3825: 26.94 | I3825: 21.32 | J3825: 24.29 | K3825: 21.86 | L3825: 23.15 | M3825: 25.99 | N3825: 24.01 | O3825: 21.28 | P3825: 25.86 | Q3825: 21.76 | R3825: 22.29 | S3825: 21.92 | T3825: 21.6 | U3825: 22.53 | V3825: 21.8 | W3825: 28.95 | X3825: 30.32 | Y3825: 19.83 | Z3825: 22.99 | AA3825: 25.53 | AB3825: 22.76 | AC3825: 30.56 | AD3825: 20.45 | AE3825: 26.72 | AF3825: 21.3
A3828: MAO DE OBRA | B3828: 6111 | C3828: SERVENTE DE OBRAS (HORISTA) | D3828: H | E3828: C | F3828: 16.28 | G3828: 15.92 | H3828: 16.01 | I3828: 15.85 | J3828: 16.04 | K3828: 15.89 | L3828: 15.65 | M3828: 16.69 | N3828: 15.3 | O3828: 15.77 | P3828: 17.36 | Q3828: 15.89 | R3828: 16.61 | S3828: 16.17 | T3828: 16.45 | U3828: 16.95 | V3828: 15.94 | W3828: 20.46 | X3828: 21.46 | Y3828: 15.98 | Z3828: 18.72 | AA3828: 15.95 | AB3828: 17.88 | AC3828: 21.06 | AD3828: 15.58 | AE3828: 21.5 | AF3828: 15.86
A4369: ENCARGOS COMPLEMENTARES | B4369: 37371 | C4369: TRANSPORTE - HORISTA (COLETADO CAIXA - ENCARGOS COMPLEMENTARES) | D4369: H | E4369: C | F4369: 0.27 | G4369: 0.48 | H4369: 1.67 | I4369: 0.38 | J4369: 0.88 | K4369: 1.09 | L4369: 1.52 | M4369: 0.66 | N4369: 0.55 | O4369: 0.51 | P4369: 0.9 | Q4369: 1.04 | R4369: 0.7 | S4369: 1.19 | T4369: 0.78 | U4369: 0.5 | V4369: 0.48 | W4369: 0.79 | X4369: 1.72 | Y4369: 0.73 | Z4369: 0.08 | AA4369: 0.85 | AB4369: 1.02 | AC4369: 0.98 | AD4369: 0.63 | AE4369: 1.07 | AF4369: 0.7

Sheet ICD
A1: SINAPI - Sistema Nacional de Pesquisa de Custos e Índices da Construção Civil
A2: RELATÓRIO DE PREÇOS DE INSUMOS - ENCARGOS SOCIAIS COM DESONERAÇÃO
A3: Mês de Referência: | B3: 01/2026 | E3: Encargos sociais sobre a mão de obra:
A4: Data de emissão: | B4: 23/03/2026 | E4: (COM DESONERAÇÃO) | F4: AC | G4: AL | H4: AM | I4: AP | J4: BA | K4: CE | L4: DF | M4: ES | N4: GO | O4: MA | P4: MG | Q4: MS | R4: MT | S4: PA | T4: PB | U4: PE | V4: PI | W4: PR | X4: RJ | Y4: RN | Z4: RO | AA4: RR | AB4: RS | AC4: SC | AD4: SE | AE4: SP | AF4: TO
E5: Localidade | F5: RIO BRANCO | G5: MACEIO | H5: MANAUS | I5: MACAPA | J5: SALVADOR | K5: FORTALEZA | L5: BRASILIA | M5: VITORIA | N5: GOIANIA | O5: SAO LUIS | P5: BELO HORIZONTE | Q5: CAMPO GRANDE | R5: CUIABA | S5: BELEM | T5: JOAO PESSOA | U5: RECIFE | V5: TERESINA | W5: CURITIBA | X5: RIO DE JANEIRO | Y5: NATAL | Z5: PORTO VELHO | AA5: BOA VISTA | AB5: PORTO ALEGRE | AC5: FLORIANOPOLIS | AD5: ARACAJU | AE5: SAO PAULO | AF5: PALMAS
A6: Origem de preço: | B6: C = COLETADO | C6: CR = COEFICIENTE DE REPRESENTATIVIDADE | E6: Horista | F6: 0.9688 | G6: 1.0013 | H6: 0.9835 | I6: 0.9923 | J6: 1.017 | K6: 0.9971 | L6: 0.9463 | M6: 1.0222 | N6: 0.9322 | O6: 0.9831 | P6: 1.0033 | Q6: 0.9956 | R6: 0.9089 | S6: 1.0326 | T6: 1.0206 | U6: 0.9883 | V6: 0.9796 | W6: 1.0025 | X6: 0.9688 | Y6: 1.0077 | Z6: 0.9961 | AA6: 0.9885 | AB6: 0.9612 | AC6: 0.9838 | AD6: 0.9588 | AE6: 0.9909 | AF6: 0.9923
A7: Preço em branco para determinado estado significa que não houve coleta mínima de preços no mês de referência | E7: Mensalista | F7: 0.5653 | G7: 0.5859 | H7: 0.582 | I7: 0.5746 | J7: 0.6013 | K7: 0.5974 | L7: 0.5745 | M7: 0.6106 | N7: 0.5747 | O7: 0.5866 | P7: 0.6106 | Q7: 0.5874 | R7: 0.5603 | S7: 0.5998 | T7: 0.5991 | U7: 0.581 | V7: 0.5891 | W7: 0.5965 | X7: 0.572 | Y7: 0.5955 | Z7: 0.5792 | AA7: 0.5772 | AB7: 0.5667 | AC7: 0.5822 | AD7: 0.5718 | AE7: 0.5851 | AF7: 0.592
A9: Acessar Fichas de Especificação Técnico dos Insumos | E9: Preços Medianos (R$):
A10: Classificação | B10: Código do Insumo | C10: Descrição do Insumo | D10: Unidade | E10: Origem de Preço | F10: AC | G10: AL | H10: AM | I10: AP | J10: BA | K10: CE | L10: DF | M10: ES | N10: GO | O10: MA | P10: MG | Q10: MS | R10: MT | S10: PA | T10: PB | U10: PE | V10: PI | W10: PR | X10: RJ | Y10: RN | Z10: RO | AA10: RR | AB10: RS | AC10: SC | AD10: SE | AE10: SP | AF10: TO
A57: MATERIAL | B57: 1 | C57: ACETILENO - RECARGA DE GAS PARA CILINDRO (NAO INCLUI TROCA/MANUTENCAO DO CILINDRO) | D57: KG | E57: C | G57: 133.33 | J57: 157.78 | K57: 101.13 | M57: 105 | N57: 97.77 | P57: 80 | Q57: 100 | R57: 119.64 | W57: 140 | AB57: 110.5 | AE57: 110
A184: ENCARGOS COMPLEMENTARES | B184: 37370 | C184: ALIMENTACAO - HORISTA (COLETADO CAIXA - ENCARGOS COMPLEMENTARES) | D184: H | E184: C | F184: 3.4 | G184: 2.68 | H184: 5.58 | I184: 0.66 | J184: 5 | K184: 4.15 | L184: 4.29 | M184: 7.63 | N184: 3.61 | O184: 2.2 | P184: 2.41 | Q184: 1.73 | R184: 2.9 | S184: 5.15 | T184: 1.82 | U184: 3.06 | V184: 2.49 | W184: 5.96 | X184: 4.78 | Y184: 4.93 | Z184: 3.76 | AA184: 3.52 | AB184: 1.82 | AC184: 0.01 | AD184: 2.96 | AE184: 4.48 | AF184: 2.39
A317: MATERIAL | B317: 34353 | C317: ARGAMASSA COLANTE AC II | D317: KG | E317: CR | F317: 2.42 | G317: 1.86 | H317: 2.38 | I317: 2.1 | J317: 1.58 | K317: 2.17 | L317: 1.19 | M317: 1.35 | N317: 1.49 | O317: 1.91 | P317: 1.26 | Q317: 1.76 | R317: 2.32 | S317: 1.67 | T317: 1.49 | U317: 1.86 | V317: 1.35 | W317: 1.41 | X317: 1.3 | Y317: 1.82 | Z317: 1.99 | AA317: 3.09 | AB317: 1.49 | AC317: 1.3 | AD317: 1.73 | AE317: 1.49 | AF317: 1.39
A320: MATERIAL | B320: 371 | C320: ARGAMASSA INDUSTRIALIZADA MULTIUSO, PARA REVESTIMENTO INTERNO E EXTERNO E ASSENTAMENTO DE BLOCOS DIVERSOS | D320: KG | E320: CR | F320: 1.42 | G320: 1.09 | H320: 1.39 | I320: 1.23 | J320: 0.92 | K320: 1.27 | L320: 0.69 | M320: 0.79 | N320: 0.87 | O320: 1.12 | P320: 0.74 | Q320: 1.03 | R320: 1.36 | S320: 0.98 | T320: 0.87 | U320: 1.09 | V320: 0.79 | W320: 0.83 | X320: 0.76 | Y320: 1.07 | Z320: 1.16 | AA320: 1.81 | AB320: 0.87 | AC320: 0.76 | AD320: 1.01 | AE320: 0.87 | AF320: 0.81
A1932: ENCARGOS COMPLEMENTARES | B1932: 43489 | C1932: EPI - FAMILIA PEDREIRO - HORISTA (ENCARGOS COMPLEMENTARES - COLETADO CAIXA) | D1932: H | E1932: C | F1932: 1.46 | G1932: 1.45 | H1932: 1.46 | I1932: 1.74 | J1932: 1.41 | K1932: 1.5 | L1932: 1.26 | M1932: 1.28 | N1932: 1.13 | O1932: 1.32 | P1932: 1.43 | Q1932: 1.43 | R1932: 1.72 | S1932: 1.76 | T1932: 1.68 | U1932: 1.47 | V1932: 1.81 | W1932: 1.64 | X1932: 1.71 | Y1932: 1.25 | Z1932: 1.56 | AA1932: 1.85 | AB1932: 1.62 | AC1932: 1.55 | AD1932: 1.28 | AE1932: 1.47 | AF1932: 1.6
A1936: ENCARGOS COMPLEMENTARES | B1936: 43491 | C1936: EPI - FAMILIA SERVENTE - HORISTA (ENCARGOS COMPLEMENTARES - COLETADO CAIXA) | D1936: H | E1936: C | F1936: 1.53 | G1936: 1.52 | H1936: 1.53 | I1936: 1.82 | J1936: 1.48 | K1936: 1.57 | L1936: 1.32 | M1936: 1.34 | N1936: 1.18 | O1936: 1.38 | P1936: 1.5 | Q1936: 1.5 | R1936: 1.8 | S1936: 1.85 | T1936: 1.75 | U1936: 1.54 | V1936: 1.89 | W1936: 1.71 | X1936: 1.79 | Y1936: 1.31 | Z1936: 1.63 | AA1936: 1.94 | AB1936: 1.7 | AC1936: 1.62 | AD1936: 1.34 | AE1936: 1.54 | AF1936: 1.67
A1993: ENCARGOS COMPLEMENTARES | B1993: 37372 | C1993: EXAMES - HORISTA (COLETADO CAIXA - ENCARGOS COMPLEMENTARES) | D1993: H | E1993: C | F1993: 1.32 | G1993: 1.4 | H1993: 1.29 | I1993: 1.3 | J1993: 1.49 | K1993: 1.48 | L1993: 1.31 | M1993: 1.62 | N1993: 1.58 | O1993: 1.36 | P1993: 1.57 | Q1993: 1.67 | R1993: 1.62 | S1993: 1.51 | T1993: 1.56 | U1993: 1.24 | V1993: 1.42 | W1993: 1.58 | X1993: 1.25 | Y1993: 1.55 | Z1993: 1.52 | AA1993: 1.36 | AB1993: 1.36 | AC1993: 1.65 | AD1993: 1.39 | AE1993: 1.43 | AF1993: 1.59
A2052: ENCARGOS COMPLEMENTARES | B2052: 43465 | C2052: FERRAMENTAS - FAMILIA PEDREIRO - HORISTA (ENCARGOS COMPLEMENTARES - COLETADO CAIXA) | D2052: H | E2052: C | F2052: 0.7 | G2052: 0.6 | H2052: 0.57 | I2052: 0.65 | J2052: 0.59 | K2052: 0.6 | L2052: 0.71 | M2052: 0.68 | N2052: 0.62 | O2052: 0.73 | P2052: 0.8 | Q2052: 0.81 | R2052: 0.74 | S2052: 0.65 | T2052: 0.63 | U2052: 0.6 | V2052: 0.9 | W2052: 0.6 | X2052: 0.64 | Y2052: 0.66 | Z2052: 0.74 | AA2052: 0.63 | AB2052: 0.71 | AC2052: 0.72 | AD2052: 0.61 | AE2052: 0.73 | AF2052: 0.83
A2056: ENCARGOS COMPLEMENTARES | B2056: 43467 | C2056: FERRAMENTAS - FAMILIA SERVENTE - HORISTA (ENCARGOS COMPLEMENTARES - COLETADO CAIXA) | D2056: H | E2056: C | F2056: 0.6 | G2056: 0.48 | H2056: 0.57 | I2056: 0.61 | J2056: 0.47 | K2056: 0.57 | L2056: 0.58 | M2056: 0.57 | N2056: 0.56 | O2056: 0.58 | P2056: 0.67 | Q2056: 0.49 | R2056: 0.6 | S2056: 0.56 | T2056: 0.58 | U2056: 0.5 | V2056: 1 | W2056: 0.42 | X2056: 0.56 | Y2056: 0.62 | Z2056: 0.63 | AA2056: 0.64 | AB2056: 0.57 | AC2056: 0.6 | AD2056: 0.49 | AE2056: 0.57 | AF2056: 0.69
A3133: MATERIAL | B3133: 2 | C3133: OXIGENIO - RECARGA DE GAS PARA CILINDRO (NAO INCLUI TROCA/MANUTENCAO DO CILINDRO) | D3133: M3 | E3133: CR | G3133: 29.22 | J3133: 34.58 | K3133: 22.16 | M3133: 23.01 | N3133: 21.42 | P3133: 17.53 | Q3133: 21.91 | R3133: 26.22 | W3133: 30.68 | AB3133: 24.21 | AE3133: 24.1
A3258: MAO DE OBRA | B3258: 4750 | C3258: PEDREIRO (HORISTA) | D3258: H | E3258: C | F3258: 21.65 | G3258: 18.77 | H3258: 20.07 | I3258: 19.74 | J3258: 22.5 | K3258: 20.25 | L3258: 21.44 | M3258: 20.46 | N3258: 22.33 | O3258: 19.71 | P3258: 23.95 | Q3258: 19.67 | R3258: 20.73 | S3258: 20.3 | T3258: 20 | U3258: 20.87 | V3258: 20.19 | W3258: 26.81 | X3258: 28.09 | Y3258: 18.37 | Z3258: 21.27 | AA3258: 23.64 | AB3258: 21.06 | AC3258: 28.26 | AD3258: 18.94 | AE3258: 24.1 | AF3258: 19.72
A3358: MATERIAL | B3358: 36178 | C3358: PISO TATIL / PODOTATIL, LADRILHO HIDRAULICO/CONCRETO, *40 X 40* CM, E= 2,5* CM, PADRAO TATIL ALERTA OU DIRECIONAL, COR NATURAL | D3358: UN | E3358: CR | F3358: 28.02 | G3358: 14.34 | H3358: 22.95 | I3358: 20.85 | J3358: 15.44 | K3358: 14.34 | L3358: 19.44 | M3358: 16.55 | N3358: 17.83 | O3358: 15.44 | P3358: 15.54 | Q3358: 17.29 | R3358: 22.03 | S3358: 15.88 | T3358: 12.8 | U3358: 13.46 | V3358: 13.57 | W3358: 12.62 | X3358: 15.88 | Y3358: 15.56 | Z3358: 21.4 | AA3358: 28.68 | AB3358: 14.17 | AC3358: 12.81 | AD3358: 16.55 | AE3358: 18.3 | AF3358: 20.85
A3730: MATERIAL | B3730: 34357 | C3730: REJUNTE CIMENTICIO, QUALQUER COR | D3730: KG | E3730: CR | F3730: 7.63 | G3730: 5.87 | H3730: 7.51 | I3730: 6.63 | J3730: 4.99 | K3730: 6.87 | L3730: 3.75 | M3730: 4.28 | N3730: 4.69 | O3730: 6.04 | P3730: 3.99 | Q3730: 5.57 | R3730: 7.34 | S3730: 5.28 | T3730: 4.69 | U3730: 5.87 | V3730: 4.28 | W3730: 4.46 | X3730: 4.11 | Y3730: 5.75 | Z3730: 6.28 | AA3730: 9.74 | AB3730: 4.69 | AC3730: 4.11 | AD3730: 5.46 | AE3730: 4.69 | AF3730: 4.4
A3804: ENCARGOS COMPLEMENTARES | B3804: 37373 | C3804: SEGURO - HORISTA (COLETADO CAIXA - ENCARGOS COMPLEMENTARES) | D3804: H | E3804: C | F3804: 0.11 | G3804: 0.11 | H3804: 0.11 | I3804: 0.01 | J3804: 0.11 | K3804: 0.11 | L3804: 0.11 | M3804: 0.11 | N3804: 0.1 | O3804: 0.11 | P3804: 0.11 | Q3804: 0.11 | R3804: 0.1 | S3804: 0.11 | T3804: 0.01 | U3804: 0.11 | V3804: 0.11 | W3804: 0.06 | X3804: 0.11 | Y3804: 0.11 | Z3804: 0.01 | AA3804: 0.01 | AB3804: 0.11 | AC3804: 0.11 | AD3804: 0.11 | AE3804: 0.11 | AF3804: 0.11
A3825: MAO DE OBRA | B3825: 6110 | C3825: SERRALHEIRO (HORISTA) | D3825: H | E3825: CR | F3825: 21.65 | G3825: 20.63 | H3825: 24.95 | I3825: 19.74 | J3825: 22.5 | K3825: 20.25 | L3825: 21.44 | M3825: 24.08 | N3825: 22.33 | O3825: 19.71 | P3825: 23.95 | Q3825: 20.13 | R3825: 20.73 | S3825: 20.3 | T3825: 20 | U3825: 20.87 | V3825: 20.19 | W3825: 26.81 | X3825: 28.09 | Y3825: 18.37 | Z3825: 21.27 | AA3825: 23.64 | AB3825: 21.06 | AC3825: 28.26 | AD3825: 18.94 | AE3825: 24.74 | AF3825: 19.72
A3828: MAO DE OBRA | B3828: 6111 | C3828: SERVENTE DE OBRAS (HORISTA) | D3828: H | E3828: C | F3828: 15.08 | G3828: 14.74 | H3828: 14.83 | I3828: 14.68 | J3828: 14.86 | K3828: 14.71 | L3828: 14.49 | M3828: 15.46 | N3828: 14.24 | O3828: 14.61 | P3828: 16.08 | Q3828: 14.7 | R3828: 15.44 | S3828: 14.98 | T3828: 15.23 | U3828: 15.7 | V3828: 14.76 | W3828: 18.94 | X3828: 19.88 | Y3828: 14.79 | Z3828: 17.32 | AA3828: 14.77 | AB3828: 16.55 | AC3828: 19.48 | AD3828: 14.43 | AE3828: 19.9 | AF3828: 14.68
A4369: ENCARGOS COMPLEMENTARES | B4369: 37371 | C4369: TRANSPORTE - HORISTA (COLETADO CAIXA - ENCARGOS COMPLEMENTARES) | D4369: H | E4369: C | F4369: 0.27 | G4369: 0.48 | H4369: 1.67 | I4369: 0.38 | J4369: 0.88 | K4369: 1.09 | L4369: 1.52 | M4369: 0.66 | N4369: 0.55 | O4369: 0.51 | P4369: 0.9 | Q4369: 1.04 | R4369: 0.7 | S4369: 1.19 | T4369: 0.78 | U4369: 0.5 | V4369: 0.48 | W4369: 0.79 | X4369: 1.72 | Y4369: 0.73 | Z4369: 0.08 | AA4369: 0.85 | AB4369: 1.02 | AC4369: 0.98 | AD4369: 0.63 | AE4369: 1.07 | AF4369: 0.7

Sheet ISE
A1: SINAPI - Sistema Nacional de Pesquisa de Custos e Índices da Construção Civil
A2: RELATÓRIO DE PREÇOS DE INSUMOS - SEM ENCARGOS SOCIAIS
A3: Mês de Referência: | B3: 01/2026
A4: Data de emissão: | B4: 23/03/2026
A6: Origem de preço: | B6: C = COLETADO | C6: CR = COEFICIENTE DE REPRESENTATIVIDADE
A7: Preço em branco para determinado estado significa que não houve coleta mínima de preços no mês de referência
A9: Acessar Fichas de Especificação Técnico dos Insumos | E9: Preços Medianos (R$):
A10: Classificação | B10: Código do Insumo | C10: Descrição do Insumo | D10: Unidade | E10: Origem de Preço | F10: AC | G10: AL | H10: AM | I10: AP | J10: BA | K10: CE | L10: DF | M10: ES | N10: GO | O10: MA | P10: MG | Q10: MS | R10: MT | S10: PA | T10: PB | U10: PE | V10: PI | W10: PR | X10: RJ | Y10: RN | Z10: RO | AA10: RR | AB10: RS | AC10: SC | AD10: SE | AE10: SP | AF10: TO
A57: MATERIAL | B57: 1 | C57: ACETILENO - RECARGA DE GAS PARA CILINDRO (NAO INCLUI TROCA/MANUTENCAO DO CILINDRO) | D57: KG | E57: C | G57: 133.33 | J57: 157.78 | K57: 101.13 | M57: 105 | N57: 97.77 | P57: 80 | Q57: 100 | R57: 119.64 | W57: 140 | AB57: 110.5 | AE57: 110
A184: ENCARGOS COMPLEMENTARES | B184: 37370 | C184: ALIMENTACAO - HORISTA (COLETADO CAIXA - ENCARGOS COMPLEMENTARES) | D184: H | E184: C | F184: 3.4 | G184: 2.68 | H184: 5.58 | I184: 0.66 | J184: 5 | K184: 4.15 | L184: 4.29 | M184: 7.63 | N184: 3.61 | O184: 2.2 | P184: 2.41 | Q184: 1.73 | R184: 2.9 | S184: 5.15 | T184: 1.82 | U184: 3.06 | V184: 2.49 | W184: 5.96 | X184: 4.78 | Y184: 4.93 | Z184: 3.76 | AA184: 3.52 | AB184: 1.82 | AC184: 0.01 | AD184: 2.96 | AE184: 4.48 | AF184: 2.39
A317: MATERIAL | B317: 34353 | C317: ARGAMASSA COLANTE AC II | D317: KG | E317: CR | F317: 2.42 | G317: 1.86 | H317: 2.38 | I317: 2.1 | J317: 1.58 | K317: 2.17 | L317: 1.19 | M317: 1.35 | N317: 1.49 | O317: 1.91 | P317: 1.26 | Q317: 1.76 | R317: 2.32 | S317: 1.67 | T317: 1.49 | U317: 1.86 | V317: 1.35 | W317: 1.41 | X317: 1.3 | Y317: 1.82 | Z317: 1.99 | AA317: 3.09 | AB317: 1.49 | AC317: 1.3 | AD317: 1.73 | AE317: 1.49 | AF317: 1.39
A320: MATERIAL | B320: 371 | C320: ARGAMASSA INDUSTRIALIZADA MULTIUSO, PARA REVESTIMENTO INTERNO E EXTERNO E ASSENTAMENTO DE BLOCOS DIVERSOS | D320: KG | E320: CR | F320: 1.42 | G320: 1.09 | H320: 1.39 | I320: 1.23 | J320: 0.92 | K320: 1.27 | L320: 0.69 | M320: 0.79 | N320: 0.87 | O320: 1.12 | P320: 0.74 | Q320: 1.03 | R320: 1.36 | S320: 0.98 | T320: 0.87 | U320: 1.09 | V320: 0.79 | W320: 0.83 | X320: 0.76 | Y320: 1.07 | Z320: 1.16 | AA320: 1.81 | AB320: 0.87 | AC320: 0.76 | AD320: 1.01 | AE320: 0.87 | AF320: 0.81
A1932: ENCARGOS COMPLEMENTARES | B1932: 43489 | C1932: EPI - FAMILIA PEDREIRO - HORISTA (ENCARGOS COMPLEMENTARES - COLETADO CAIXA) | D1932: H | E1932: C | F1932: 1.46 | G1932: 1.45 | H1932: 1.46 | I1932: 1.74 | J1932: 1.41 | K1932: 1.5 | L1932: 1.26 | M1932: 1.28 | N1932: 1.13 | O1932: 1.32 | P1932: 1.43 | Q1932: 1.43 | R1932: 1.72 | S1932: 1.76 | T1932: 1.68 | U1932: 1.47 | V1932: 1.81 | W1932: 1.64 | X1932: 1.71 | Y1932: 1.25 | Z1932: 1.56 | AA1932: 1.85 | AB1932: 1.62 | AC1932: 1.55 | AD1932: 1.28 | AE1932: 1.47 | AF1932: 1.6
A1936: ENCARGOS COMPLEMENTARES | B1936: 43491 | C1936: EPI - FAMILIA SERVENTE - HORISTA (ENCARGOS COMPLEMENTARES - COLETADO CAIXA) | D1936: H | E1936: C | F1936: 1.53 | G1936: 1.52 | H1936: 1.53 | I1936: 1.82 | J1936: 1.48 | K1936: 1.57 | L1936: 1.32 | M1936: 1.34 | N1936: 1.18 | O1936: 1.38 | P1936: 1.5 | Q1936: 1.5 | R1936: 1.8 | S1936: 1.85 | T1936: 1.75 | U1936: 1.54 | V1936: 1.89 | W1936: 1.71 | X1936: 1.79 | Y1936: 1.31 | Z1936: 1.63 | AA1936: 1.94 | AB1936: 1.7 | AC1936: 1.62 | AD1936: 1.34 | AE1936: 1.54 | AF1936: 1.67
A1993: ENCARGOS COMPLEMENTARES | B1993: 37372 | C1993: EXAMES - HORISTA (COLETADO CAIXA - ENCARGOS COMPLEMENTARES) | D1993: H | E1993: C | F1993: 1.32 | G1993: 1.4 | H1993: 1.29 | I1993: 1.3 | J1993: 1.49 | K1993: 1.48 | L1993: 1.31 | M1993: 1.62 | N1993: 1.58 | O1993: 1.36 | P1993: 1.57 | Q1993: 1.67 | R1993: 1.62 | S1993: 1.51 | T1993: 1.56 | U1993: 1.24 | V1993: 1.42 | W1993: 1.58 | X1993: 1.25 | Y1993: 1.55 | Z1993: 1.52 | AA1993: 1.36 | AB1993: 1.36 | AC1993: 1.65 | AD1993: 1.39 | AE1993: 1.43 | AF1993: 1.59
A2052: ENCARGOS COMPLEMENTARES | B2052: 43465 | C2052: FERRAMENTAS - FAMILIA PEDREIRO - HORISTA (ENCARGOS COMPLEMENTARES - COLETADO CAIXA) | D2052: H | E2052: C | F2052: 0.7 | G2052: 0.6 | H2052: 0.57 | I2052: 0.65 | J2052: 0.59 | K2052: 0.6 | L2052: 0.71 | M2052: 0.68 | N2052: 0.62 | O2052: 0.73 | P2052: 0.8 | Q2052: 0.81 | R2052: 0.74 | S2052: 0.65 | T2052: 0.63 | U2052: 0.6 | V2052: 0.9 | W2052: 0.6 | X2052: 0.64 | Y2052: 0.66 | Z2052: 0.74 | AA2052: 0.63 | AB2052: 0.71 | AC2052: 0.72 | AD2052: 0.61 | AE2052: 0.73 | AF2052: 0.83
A2056: ENCARGOS COMPLEMENTARES | B2056: 43467 | C2056: FERRAMENTAS - FAMILIA SERVENTE - HORISTA (ENCARGOS COMPLEMENTARES - COLETADO CAIXA) | D2056: H | E2056: C | F2056: 0.6 | G2056: 0.48 | H2056: 0.57 | I2056: 0.61 | J2056: 0.47 | K2056: 0.57 | L2056: 0.58 | M2056: 0.57 | N2056: 0.56 | O2056: 0.58 | P2056: 0.67 | Q2056: 0.49 | R2056: 0.6 | S2056: 0.56 | T2056: 0.58 | U2056: 0.5 | V2056: 1 | W2056: 0.42 | X2056: 0.56 | Y2056: 0.62 | Z2056: 0.63 | AA2056: 0.64 | AB2056: 0.57 | AC2056: 0.6 | AD2056: 0.49 | AE2056: 0.57 | AF2056: 0.69
A3133: MATERIAL | B3133: 2 | C3133: OXIGENIO - RECARGA DE GAS PARA CILINDRO (NAO INCLUI TROCA/MANUTENCAO DO CILINDRO) | D3133: M3 | E3133: CR | G3133: 29.22 | J3133: 34.58 | K3133: 22.16 | M3133: 23.01 | N3133: 21.42 | P3133: 17.53 | Q3133: 21.91 | R3133: 26.22 | W3133: 30.68 | AB3133: 24.21 | AE3133: 24.1
A3258: MAO DE OBRA | B3258: 4750 | C3258: PEDREIRO (HORISTA) | D3258: H | E3258: C | F3258: 11 | G3258: 9.38 | H3258: 10.12 | I3258: 9.91 | J3258: 11.16 | K3258: 10.14 | L3258: 11.02 | M3258: 10.12 | N3258: 11.56 | O3258: 9.94 | P3258: 11.96 | Q3258: 9.86 | R3258: 10.86 | S3258: 9.99 | T3258: 9.9 | U3258: 10.5 | V3258: 10.2 | W3258: 13.39 | X3258: 14.27 | Y3258: 9.15 | Z3258: 10.66 | AA3258: 11.89 | AB3258: 10.74 | AC3258: 14.25 | AD3258: 9.67 | AE3258: 12.11 | AF3258: 9.9
A3358: MATERIAL | B3358: 36178 | C3358: PISO TATIL / PODOTATIL, LADRILHO HIDRAULICO/CONCRETO, *40 X 40* CM, E= 2,5* CM, PADRAO TATIL ALERTA OU DIRECIONAL, COR NATURAL | D3358: UN | E3358: CR | F3358: 28.02 | G3358: 14.34 | H3358: 22.95 | I3358: 20.85 | J3358: 15.44 | K3358: 14.34 | L3358: 19.44 | M3358: 16.55 | N3358: 17.83 | O3358: 15.44 | P3358: 15.54 | Q3358: 17.29 | R3358: 22.03 | S3358: 15.88 | T3358: 12.8 | U3358: 13.46 | V3358: 13.57 | W3358: 12.62 | X3358: 15.88 | Y3358: 15.56 | Z3358: 21.4 | AA3358: 28.68 | AB3358: 14.17 | AC3358: 12.81 | AD3358: 16.55 | AE3358: 18.3 | AF3358: 20.85
A3730: MATERIAL | B3730: 34357 | C3730: REJUNTE CIMENTICIO, QUALQUER COR | D3730: KG | E3730: CR | F3730: 7.63 | G3730: 5.87 | H3730: 7.51 | I3730: 6.63 | J3730: 4.99 | K3730: 6.87 | L3730: 3.75 | M3730: 4.28 | N3730: 4.69 | O3730: 6.04 | P3730: 3.99 | Q3730: 5.57 | R3730: 7.34 | S3730: 5.28 | T3730: 4.69 | U3730: 5.87 | V3730: 4.28 | W3730: 4.46 | X3730: 4.11 | Y3730: 5.75 | Z3730: 6.28 | AA3730: 9.74 | AB3730: 4.69 | AC3730: 4.11 | AD3730: 5.46 | AE3730: 4.69 | AF3730: 4.4
A3804: ENCARGOS COMPLEMENTARES | B3804: 37373 | C3804: SEGURO - HORISTA (COLETADO CAIXA - ENCARGOS COMPLEMENTARES) | D3804: H | E3804: C | F3804: 0.11 | G3804: 0.11 | H3804: 0.11 | I3804: 0.01 | J3804: 0.11 | K3804: 0.11 | L3804: 0.11 | M3804: 0.11 | N3804: 0.1 | O3804: 0.11 | P3804: 0.11 | Q3804: 0.11 | R3804: 0.1 | S3804: 0.11 | T3804: 0.01 | U3804: 0.11 | V3804: 0.11 | W3804: 0.06 | X3804: 0.11 | Y3804: 0.11 | Z3804: 0.01 | AA3804: 0.01 | AB3804: 0.11 | AC3804: 0.11 | AD3804: 0.11 | AE3804: 0.11 | AF3804: 0.11
A3825: MAO DE OBRA | B3825: 6110 | C3825: SERRALHEIRO (HORISTA) | D3825: H | E3825: CR | F3825: 11 | G3825: 10.31 | H3825: 12.58 | I3825: 9.91 | J3825: 11.16 | K3825: 10.14 | L3825: 11.02 | M3825: 11.91 | N3825: 11.56 | O3825: 9.94 | P3825: 11.96 | Q3825: 10.09 | R3825: 10.86 | S3825: 9.99 | T3825: 9.9 | U3825: 10.5 | V3825: 10.2 | W3825: 13.39 | X3825: 14.27 | Y3825: 9.15 | Z3825: 10.66 | AA3825: 11.89 | AB3825: 10.74 | AC3825: 14.25 | AD3825: 9.67 | AE3825: 12.43 | AF3825: 9.9
A3828: MAO DE OBRA | B3828: 6111 | C3828: SERVENTE DE OBRAS (HORISTA) | D3828: H | E3828: C | F3828: 7.66 | G3828: 7.37 | H3828: 7.48 | I3828: 7.37 | J3828: 7.37 | K3828: 7.37 | L3828: 7.45 | M3828: 7.65 | N3828: 7.37 | O3828: 7.37 | P3828: 8.03 | Q3828: 7.37 | R3828: 8.09 | S3828: 7.37 | T3828: 7.54 | U3828: 7.9 | V3828: 7.46 | W3828: 9.46 | X3828: 10.1 | Y3828: 7.37 | Z3828: 8.68 | AA3828: 7.43 | AB3828: 8.44 | AC3828: 9.82 | AD3828: 7.37 | AE3828: 10 | AF3828: 7.37
A4369: ENCARGOS COMPLEMENTARES | B4369: 37371 | C4369: TRANSPORTE - HORISTA (COLETADO CAIXA - ENCARGOS COMPLEMENTARES) | D4369: H | E4369: C | F4369: 0.27 | G4369: 0.48 | H4369: 1.67 | I4369: 0.38 | J4369: 0.88 | K4369: 1.09 | L4369: 1.52 | M4369: 0.66 | N4369: 0.55 | O4369: 0.51 | P4369: 0.9 | Q4369: 1.04 | R4369: 0.7 | S4369: 1.19 | T4369: 0.78 | U4369: 0.5 | V4369: 0.48 | W4369: 0.79 | X4369: 1.72 | Y4369: 0.73 | Z4369: 0.08 | AA4369: 0.85 | AB4369: 1.02 | AC4369: 0.98 | AD4369: 0.63 | AE4369: 1.07 | AF4369: 0.7

Sheet CSD
A1: SINAPI - Sistema Nacional de Pesquisa de Custos e Índices da Construção Civil
A2: RELATÓRIO DE CUSTOS DE COMPOSIÇÕES - ENCARGOS SOCIAIS SEM DESONERAÇÃO
A3: Mês de Referência: | B3: 01/2026 | D3: Encargos sociais sobre a mão de obra:
A4: Data de emissão: | B4: 23/03/2026 | D4: (SEM DESONERAÇÃO) | E4: AC | G4: AL | I4: AM | K4: AP | M4: BA | O4: CE | Q4: DF | S4: ES | U4: GO | W4: MA | Y4: MG | AA4: MS | AC4: MT | AE4: PA | AG4: PB | AI4: PE | AK4: PI | AM4: PR | AO4: RJ | AQ4: RN | AS4: RO | AU4: RR | AW4: RS | AY4: SC | BA4: SE | BC4: SP | BE4: TO
D5: Localidade | E5: RIO BRANCO | G5: MACEIO | I5: MANAUS | K5: MACAPA | M5: SALVADOR | O5: FORTALEZA | Q5: BRASILIA | S5: VITORIA | U5: GOIANIA | W5: SAO LUIS | Y5: BELO HORIZONTE | AA5: CAMPO GRANDE | AC5: CUIABA | AE5: BELEM | AG5: JOAO PESSOA | AI5: RECIFE | AK5: TERESINA | AM5: CURITIBA | AO5: RIO DE JANEIRO | AQ5: NATAL | AS5: PORTO VELHO | AU5: BOA VISTA | AW5: PORTO ALEGRE | AY5: FLORIANOPOLIS | BA5: ARACAJU | BC5: SAO PAULO | BE5: PALMAS
A6: Observação: | B6: %AS (porcentagem Atribuído São Paulo) corresponde a porcentagem do custo total da | D6: Horista | E6: 1.1261 | G6: 1.1612 | I6: 1.1416 | K6: 1.1518 | M6: 1.1773 | O6: 1.1561 | Q6: 1.1008 | S6: 1.183 | U6: 1.0772 | W6: 1.1411 | Y6: 1.1623 | AA6: 1.1571 | AC6: 1.0533 | AE6: 1.1942 | AG6: 1.1819 | AI6: 1.1463 | AK6: 1.1378 | AM6: 1.1628 | AO6: 1.1249 | AQ6: 1.1683 | AS6: 1.1571 | AU6: 1.1479 | AW6: 1.1195 | AY6: 1.1447 | BA6: 1.1151 | BC6: 1.1501 | BE6: 1.1523
B7: composição que foi obtida utilizando preços de insumos de São Paulo por indisponibilidade | D7: Mensalista | E7: 0.6903 | G7: 0.7125 | I7: 0.708 | K7: 0.7006 | M7: 0.7285 | O7: 0.7246 | Q7: 0.6994 | S7: 0.7385 | U7: 0.6928 | W7: 0.713 | Y7: 0.7383 | AA7: 0.7157 | AC7: 0.6783 | AE7: 0.727 | AG7: 0.7266 | AI7: 0.7067 | AK7: 0.7159 | AM7: 0.7242 | AO7: 0.6966 | AQ7: 0.7229 | AS7: 0.7065 | AU7: 0.7035 | AW7: 0.6929 | AY7: 0.7103 | BA7: 0.6972 | BC7: 0.7118 | BE7: 0.7198
B8: dos preços de insumos necessários à composição no estado em questão. Custo zerado (hífen)
B9: indica que pelo menos um dos itens da composição não tem custo/preço. | E9: AC | G9: AL | I9: AM | K9: AP | M9: BA | O9: CE | Q9: DF | S9: ES | U9: GO | W9: MA | Y9: MG | AA9: MS | AC9: MT | AE9: PA | AG9: PB | AI9: PE | AK9: PI | AM9: PR | AO9: RJ | AQ9: RN | AS9: RO | AU9: RR | AW9: RS | AY9: SC | BA9: SE | BC9: SP | BE9: TO
A10: Grupo | B10: Código da Composição | C10: Descrição | D10: Unidade | E10: Custo (R$) | F10: %AS | G10: Custo (R$) | H10: %AS | I10: Custo (R$) | J10: %AS | K10: Custo (R$) | L10: %AS | M10: Custo (R$) | N10: %AS | O10: Custo (R$) | P10: %AS | Q10: Custo (R$) | R10: %AS | S10: Custo (R$) | T10: %AS | U10: Custo (R$) | V10: %AS | W10: Custo (R$) | X10: %AS | Y10: Custo (R$) | Z10: %AS | AA10: Custo (R$) | AB10: %AS | AC10: Custo (R$) | AD10: %AS | AE10: Custo (R$) | AF10: %AS | AG10: Custo (R$) | AH10: %AS | AI10: Custo (R$) | AJ10: %AS | AK10: Custo (R$) | AL10: %AS | AM10: Custo (R$) | AN10: %AS | AO10: Custo (R$) | AP10: %AS | AQ10: Custo (R$) | AR10: %AS | AS10: Custo (R$) | AT10: %AS | AU10: Custo (R$) | AV10: %AS | AW10: Custo (R$) | AX10: %AS | AY10: Custo (R$) | AZ10: %AS | BA10: Custo (R$) | BB10: %AS | BC10: Custo (R$) | BD10: %AS | BE10: Custo (R$) | BF10: %AS
A11: Acessibilidade | B11: =HYPERLINK("#"&CELL("address",OFFSET(Analítico!$B$1,MATCH(104658,Analítico!$B:$B,0)-1,3)),104658) -> 0 | C11: PISO PODOTÁTIL DE ALERTA OU DIRECIONAL, DE CONCRETO, ASSENTADO SOBRE ARGAMASSA. AF_03/2024 | D11: M2 | E11: 253.45 | F11: 0 | G11: 156.56 | H11: 0 | I11: 225.64 | J11: 0 | K11: 197.64 | L11: 0 | M11: 169.1 | N11: 0 | O11: 164.82 | P11: 0 | Q11: 189.38 | R11: 0 | S11: 178.3 | T11: 0 | U11: 178.92 | V11: 0 | W11: 163.59 | X11: 0 | Y11: 165.14 | Z11: 0 | AA11: 175.12 | AB11: 0 | AC11: 214.63 | AD11: 0 | AE11: 173.16 | AF11: 0 | AG11: 144.37 | AH11: 0 | AI11: 154.23 | AJ11: 0 | AK11: 149.09 | AL11: 0 | AM11: 160.31 | AN11: 0 | AO11: 181.78 | AP11: 0 | AQ11: 168.74 | AR11: 0 | AS11: 210.5 | AT11: 0 | AU11: 266.95 | AV11: 0 | AW11: 156.01 | AX11: 0 | AY11: 151.63 | AZ11: 0 | BA11: 169.75 | BB11: 0 | BC11: 194.52 | BD11: 0 | BE11: 195.61 | BF11: 0
A112: Argamassas | B112: =HYPERLINK("#"&CELL("address",OFFSET(Analítico!$B$1,MATCH(87398,Analítico!$B:$B,0)-1,3)),87398) -> 0 | C112: ARGAMASSA INDUSTRIALIZADA MULTIUSO PARA REVESTIMENTOS E ASSENTAMENTO DA ALVENARIA, PREPARO MANUAL. AF_08/2019 | D112: M3 | E112: 2984.07 | F112: 0 | G112: 2348.66 | H112: 0 | I112: 2968.16 | J112: 0 | K112: 2588.58 | L112: 0 | M112: 2063.74 | N112: 0 | O112: 2717.44 | P112: 0 | Q112: 1620.23 | R112: 0 | S112: 1857.83 | T112: 0 | U112: 1936.38 | V112: 0 | W112: 2396.8 | X112: 0 | Y112: 1711.83 | Z112: 0 | AA112: 2233.24 | AB112: 0 | AC112: 2881.12 | AD112: 0 | AE112: 2190.61 | AF112: 0 | AG112: 1937.52 | AH112: 0 | AI112: 2365.4 | AJ112: 0 | AK112: 1790.97 | AL112: 0 | AM112: 1964.15 | AN112: 0 | AO112: 1840.79 | AP112: 0 | AQ112: 2344.1 | AR112: 0 | AS112: 2529.05 | AT112: 0 | AU112: 3730.61 | AV112: 0 | AW112: 1956.9 | AX112: 0 | AY112: 1769.65 | AZ112: 0 | BA112: 2196.32 | BB112: 0 | BC112: 2036.47 | BD112: 0 | BE112: 1824.75 | BF112: 0
A1105: Brises | B1105: =HYPERLINK("#"&CELL("address",OFFSET(Analítico!$B$1,MATCH(104943,Analítico!$B:$B,0)-1,3)),104943) -> 0 | C1105: FORNECIMENTO E INSTALAÇÃO DE CONJUNTO DE BRISE EM REQUADRO DE ALUMÍNIO DESLIZANTE, COM PERFIS INTERNOS TUBULARES FIXOS, COM PINTURA ELETROSTÁTICA BRANCA, ACABAMENTO, 150 CM X 265 CM. AF_03/2024 | D1105: M2 | E1105: 0 | G1105: 0 | I1105: 0 | K1105: 0 | M1105: 0 | O1105: 0 | Q1105: 0 | S1105: 0 | U1105: 0 | W1105: 0 | Y1105: 0 | AA1105: 0 | AC1105: 0 | AE1105: 0 | AG1105: 0 | AI1105: 0 | AK1105: 0 | AM1105: 0 | AO1105: 0 | AQ1105: 0 | AS1105: 0 | AU1105: 0 | AW1105: 0 | AY1105: 0 | BA1105: 0 | BC1105: 0 | BE1105: 0
A1493: Custos Horários Produtivo e Improdutivo dos Equipamentos | B1493: =HYPERLINK("#"&CELL("address",OFFSET(Analítico!$B$1,MATCH(102953,Analítico!$B:$B,0)-1,3)),102953) -> 0 | C1493: BETONEIRA CAPACIDADE NOMINAL DE 250 L, CAPACIDADE DE MISTURA DE 175 L, MOTOR ELÉTRICO MONOFÁSICO POTÊNCIA 1CV - CHI DIURNO. AF_05/2023 | D1493: CHI | E1493: 0 | G1493: 0 | I1493: 0 | K1493: 0 | M1493: 0 | O1493: 0 | Q1493: 0 | S1493: 0 | U1493: 0 | W1493: 0 | Y1493: 0 | AA1493: 0 | AC1493: 0 | AE1493: 0 | AG1493: 0 | AI1493: 0 | AK1493: 0 | AM1493: 0 | AO1493: 0 | AQ1493: 0 | AS1493: 0 | AU1493: 0 | AW1493: 0 | AY1493: 0 | BA1493: 0 | BC1493: 0 | BE1493: 0
A1981: Depreciação, Juros, Impostos e Seguros, Manutenção e Materiais na Operação dos Equipamentos | B1981: =HYPERLINK("#"&CELL("address",OFFSET(Analítico!$B$1,MATCH(92715,Analítico!$B:$B,0)-1,3)),92715) -> 0 | C1981: APARELHO PARA CORTE E SOLDA OXI-ACETILENO SOBRE RODAS, INCLUSIVE CILINDROS E MAÇARICOS - MATERIAIS NA OPERAÇÃO. AF_05/2023 | D1981: H | E1981: 114.72 | F1981: 1 | G1981: 139.08 | H1981: 0 | I1981: 114.72 | J1981: 1 | K1981: 114.72 | L1981: 1 | M1981: 164.59 | N1981: 0 | O1981: 105.48 | P1981: 0 | Q1981: 114.72 | R1981: 1 | S1981: 109.52 | T1981: 0 | U1981: 101.96 | V1981: 0 | W1981: 114.72 | X1981: 1 | Y1981: 83.44 | Z1981: 0 | AA1981: 104.3 | AB1981: 0 | AC1981: 124.8 | AD1981: 0 | AE1981: 114.72 | AF1981: 1 | AG1981: 114.72 | AH1981: 1 | AI1981: 114.72 | AJ1981: 1 | AK1981: 114.72 | AL1981: 1 | AM1981: 146.04 | AN1981: 0 | AO1981: 114.72 | AP1981: 1 | AQ1981: 114.72 | AR1981: 1 | AS1981: 114.72 | AT1981: 1 | AU1981: 114.72 | AV1981: 1 | AW1981: 115.24 | AX1981: 0 | AY1981: 114.72 | AZ1981: 1 | BA1981: 114.72 | BB1981: 1 | BC1981: 114.72 | BD1981: 0 | BE1981: 114.72 | BF1981: 1
A1999: Depreciação, Juros, Impostos e Seguros, Manutenção e Materiais na Operação dos Equipamentos | B1999: =HYPERLINK("#"&CELL("address",OFFSET(Analítico!$B$1,MATCH(102948,Analítico!$B:$B,0)-1,3)),102948) -> 0 | C1999: BETONEIRA CAPACIDADE NOMINAL DE 250 L, CAPACIDADE DE MISTURA DE 175 L, MOTOR ELÉTRICO MONOFÁSICO POTÊNCIA 1CV - DEPRECIAÇÃO. AF_05/2023 | D1999: H | E1999: 0 | G1999: 0 | I1999: 0 | K1999: 0 | M1999: 0 | O1999: 0 | Q1999: 0 | S1999: 0 | U1999: 0 | W1999: 0 | Y1999: 0 | AA1999: 0 | AC1999: 0 | AE1999: 0 | AG1999: 0 | AI1999: 0 | AK1999: 0 | AM1999: 0 | AO1999: 0 | AQ1999: 0 | AS1999: 0 | AU1999: 0 | AW1999: 0 | AY1999: 0 | BA1999: 0 | BC1999: 0 | BE1999: 0
A2000: Depreciação, Juros, Impostos e Seguros, Manutenção e Materiais na Operação dos Equipamentos | B2000: =HYPERLINK("#"&CELL("address",OFFSET(Analítico!$B$1,MATCH(102949,Analítico!$B:$B,0)-1,3)),102949) -> 0 | C2000: BETONEIRA CAPACIDADE NOMINAL DE 250 L, CAPACIDADE DE MISTURA DE 175 L, MOTOR ELÉTRICO MONOFÁSICO POTÊNCIA 1CV - JUROS. AF_05/2023 | D2000: H | E2000: 0 | G2000: 0 | I2000: 0 | K2000: 0 | M2000: 0 | O2000: 0 | Q2000: 0 | S2000: 0 | U2000: 0 | W2000: 0 | Y2000: 0 | AA2000: 0 | AC2000: 0 | AE2000: 0 | AG2000: 0 | AI2000: 0 | AK2000: 0 | AM2000: 0 | AO2000: 0 | AQ2000: 0 | AS2000: 0 | AU2000: 0 | AW2000: 0 | AY2000: 0 | BA2000: 0 | BC2000: 0 | BE2000: 0
A7249: Livro SINAPI: Cálculos e Parâmetros | B7249: =HYPERLINK("#"&CELL("address",OFFSET(Analítico!$B$1,MATCH(95371,Analítico!$B:$B,0)-1,3)),95371) -> 0 | C7249: CURSO DE CAPACITAÇÃO PARA PEDREIRO (ENCARGOS COMPLEMENTARES) - HORISTA | D7249: H | E7249: 0.49 | F7249: 0 | G7249: 0.42 | H7249: 0 | I7249: 0.45 | J7249: 0 | K7249: 0.45 | L7249: 0 | M7249: 0.51 | N7249: 0 | O7249: 0.46 | P7249: 0 | Q7249: 0.49 | R7249: 0 | S7249: 0.46 | T7249: 0 | U7249: 0.5 | V7249: 0 | W7249: 0.45 | X7249: 0 | Y7249: 0.54 | Z7249: 0 | AA7249: 0.45 | AB7249: 0 | AC7249: 0.47 | AD7249: 0 | AE7249: 0.46 | AF7249: 0 | AG7249: 0.45 | AH7249: 0 | AI7249: 0.47 | AJ7249: 0 | AK7249: 0.46 | AL7249: 0 | AM7249: 0.61 | AN7249: 0 | AO7249: 0.64 | AP7249: 0 | AQ7249: 0.42 | AR7249: 0 | AS7249: 0.48 | AT7249: 0 | AU7249: 0.54 | AV7249: 0 | AW7249: 0.48 | AX7249: 0 | AY7249: 0.64 | AZ7249: 0 | BA7249: 0.43 | BB7249: 0 | BC7249: 0.55 | BD7249: 0 | BE7249: 0.45 | BF7249: 0
A7260: Livro SINAPI: Cálculos e Parâmetros | B7260: =HYPERLINK("#"&CELL("address",OFFSET(Analítico!$B$1,MATCH(95377,Analítico!$B:$B,0)-1,3)),95377) -> 0 | C7260: CURSO DE CAPACITAÇÃO PARA SERRALHEIRO (ENCARGOS COMPLEMENTARES) - HORISTA | D7260: H | E7260: 0.26 | F7260: 0 | G7260: 0.25 | H7260: 0 | I7260: 0.31 | J7260: 0 | K7260: 0.24 | L7260: 0 | M7260: 0.28 | N7260: 0 | O7260: 0.25 | P7260: 0 | Q7260: 0.26 | R7260: 0 | S7260: 0.29 | T7260: 0 | U7260: 0.27 | V7260: 0 | W7260: 0.24 | X7260: 0 | Y7260: 0.29 | Z7260: 0 | AA7260: 0.25 | AB7260: 0 | AC7260: 0.25 | AD7260: 0 | AE7260: 0.25 | AF7260: 0 | AG7260: 0.24 | AH7260: 0 | AI7260: 0.25 | AJ7260: 0 | AK7260: 0.25 | AL7260: 0 | AM7260: 0.33 | AN7260: 0 | AO7260: 0.34 | AP7260: 0 | AQ7260: 0.22 | AR7260: 0 | AS7260: 0.26 | AT7260: 0 | AU7260: 0.29 | AV7260: 0 | AW7260: 0.26 | AX7260: 0 | AY7260: 0.35 | AZ7260: 0 | BA7260: 0.23 | BB7260: 0 | BC7260: 0.3 | BD7260: 0 | BE7260: 0.24 | BF7260: 0
A7262: Livro SINAPI: Cálculos e Parâmetros | B7262: =HYPERLINK("#"&CELL("address",OFFSET(Analítico!$B$1,MATCH(95378,Analítico!$B:$B,0)-1,3)),95378) -> 0 | C7262: CURSO DE CAPACITAÇÃO PARA SERVENTE (ENCARGOS COMPLEMENTARES) - HORISTA | D7262: H | E7262: 0.34 | F7262: 0 | G7262: 0.33 | H7262: 0 | I7262: 0.33 | J7262: 0 | K7262: 0.33 | L7262: 0 | M7262: 0.34 | N7262: 0 | O7262: 0.33 | P7262: 0 | Q7262: 0.33 | R7262: 0 | S7262: 0.35 | T7262: 0 | U7262: 0.32 | V7262: 0 | W7262: 0.33 | X7262: 0 | Y7262: 0.36 | Z7262: 0 | AA7262: 0.33 | AB7262: 0 | AC7262: 0.35 | AD7262: 0 | AE7262: 0.34 | AF7262: 0 | AG7262: 0.34 | AH7262: 0 | AI7262: 0.35 | AJ7262: 0 | AK7262: 0.33 | AL7262: 0 | AM7262: 0.43 | AN7262: 0 | AO7262: 0.45 | AP7262: 0 | AQ7262: 0.33 | AR7262: 0 | AS7262: 0.39 | AT7262: 0 | AU7262: 0.33 | AV7262: 0 | AW7262: 0.37 | AX7262: 0 | AY7262: 0.44 | AZ7262: 0 | BA7262: 0.33 | BB7262: 0 | BC7262: 0.45 | BD7262: 0 | BE7262: 0.33 | BF7262: 0
A7377: Livro SINAPI: Cálculos e Parâmetros | B7377: =HYPERLINK("#"&CELL("address",OFFSET(Analítico!$B$1,MATCH(88309,Analítico!$B:$B,0)-1,3)),88309) -> 0 | C7377: PEDREIRO COM ENCARGOS COMPLEMENTARES | D7377: H | E7377: 31.13 | F7377: 0 | G7377: 27.41 | H7377: 0 | I7377: 32.8 | J7377: 0 | K7377: 26.51 | L7377: 0 | M7377: 34.28 | N7377: 0 | O7377: 31.25 | P7377: 0 | Q7377: 32.84 | R7377: 0 | S7377: 34.53 | T7377: 0 | U7377: 32.1 | V7377: 0 | W7377: 27.96 | X7377: 0 | Y7377: 33.62 | Z7377: 0 | AA7377: 28.5 | AB7377: 0 | AC7377: 30.54 | AD7377: 0 | AE7377: 32.75 | AF7377: 0 | AG7377: 28.53 | AH7377: 0 | AI7377: 29.98 | AJ7377: 0 | AK7377: 29.47 | AL7377: 0 | AM7377: 40.19 | AN7377: 0 | AO7377: 41.17 | AP7377: 0 | AQ7377: 29.48 | AR7377: 0 | AS7377: 31.14 | AT7377: 0 | AU7377: 34.29 | AV7377: 0 | AW7377: 29.88 | AX7377: 0 | AY7377: 36.22 | AZ7377: 0 | BA7377: 27.86 | BB7377: 0 | BC7377: 35.87 | BD7377: 0 | BE7377: 28.97 | BF7377: 0
A7388: Livro SINAPI: Cálculos e Parâmetros | B7388: =HYPERLINK("#"&CELL("address",OFFSET(Analítico!$B$1,MATCH(88315,Analítico!$B:$B,0)-1,3)),88315) -> 0 | C7388: SERRALHEIRO COM ENCARGOS COMPLEMENTARES | D7388: H | E7388: 30.9 | F7388: 0 | G7388: 29.25 | H7388: 0 | I7388: 37.93 | J7388: 0 | K7388: 26.3 | L7388: 0 | M7388: 34.05 | N7388: 0 | O7388: 31.04 | P7388: 0 | Q7388: 32.61 | R7388: 0 | S7388: 38.26 | T7388: 0 | U7388: 31.87 | V7388: 0 | W7388: 27.75 | X7388: 0 | Y7388: 33.37 | Z7388: 0 | AA7388: 28.8 | AB7388: 0 | AC7388: 30.32 | AD7388: 0 | AE7388: 32.54 | AF7388: 0 | AG7388: 28.32 | AH7388: 0 | AI7388: 29.76 | AJ7388: 0 | AK7388: 29.26 | AL7388: 0 | AM7388: 39.91 | AN7388: 0 | AO7388: 40.87 | AP7388: 0 | AQ7388: 29.28 | AR7388: 0 | AS7388: 30.92 | AT7388: 0 | AU7388: 34.04 | AV7388: 0 | AW7388: 29.66 | AX7388: 0 | AY7388: 35.93 | AZ7388: 0 | BA7388: 27.66 | BB7388: 0 | BC7388: 36.31 | BD7388: 0 | BE7388: 28.76 | BF7388: 0
A7390: Livro SINAPI: Cálculos e Parâmetros | B7390: =HYPERLINK("#"&CELL("address",OFFSET(Analítico!$B$1,MATCH(88316,Analítico!$B:$B,0)-1,3)),88316) -> 0 | C7390: SERVENTE COM ENCARGOS COMPLEMENTARES | D7390: H | E7390: 23.85 | F7390: 0 | G7390: 22.92 | H7390: 0 | I7390: 27.09 | J7390: 0 | K7390: 20.96 | L7390: 0 | M7390: 25.81 | N7390: 0 | O7390: 25.19 | P7390: 0 | Q7390: 25.11 | R7390: 0 | S7390: 28.97 | T7390: 0 | U7390: 23.2 | V7390: 0 | W7390: 22.24 | X7390: 0 | Y7390: 24.88 | Z7390: 0 | AA7390: 22.76 | AB7390: 0 | AC7390: 24.68 | AD7390: 0 | AE7390: 26.88 | AF7390: 0 | AG7390: 23.29 | AH7390: 0 | AI7390: 24.25 | AJ7390: 0 | AK7390: 23.66 | AL7390: 0 | AM7390: 31.41 | AN7390: 0 | AO7390: 32.12 | AP7390: 0 | AQ7390: 25.56 | AR7390: 0 | AS7390: 26.74 | AT7390: 0 | AU7390: 24.6 | AV7390: 0 | AW7390: 24.83 | AX7390: 0 | AY7390: 26.47 | AZ7390: 0 | BA7390: 22.83 | BB7390: 0 | BC7390: 31.15 | BD7390: 0 | BE7390: 23.34 | BF7390: 0

Sheet CCD
A1: SINAPI - Sistema Nacional de Pesquisa de Custos e Índices da Construção Civil
A2: RELATÓRIO DE CUSTOS DE COMPOSIÇÕES - ENCARGOS SOCIAIS COM DESONERAÇÃO
A3: Mês de Referência: | B3: 01/2026 | D3: Encargos sociais sobre a mão de obra:
A4: Data de emissão: | B4: 23/03/2026 | D4: (COM DESONERAÇÃO) | E4: AC | G4: AL | I4: AM | K4: AP | M4: BA | O4: CE | Q4: DF | S4: ES | U4: GO | W4: MA | Y4: MG | AA4: MS | AC4: MT | AE4: PA | AG4: PB | AI4: PE | AK4: PI | AM4: PR | AO4: RJ | AQ4: RN | AS4: RO | AU4: RR | AW4: RS | AY4: SC | BA4: SE | BC4: SP | BE4: TO
D5: Localidade | E5: RIO BRANCO | G5: MACEIO | I5: MANAUS | K5: MACAPA | M5: SALVADOR | O5: FORTALEZA | Q5: BRASILIA | S5: VITORIA | U5: GOIANIA | W5: SAO LUIS | Y5: BELO HORIZONTE | AA5: CAMPO GRANDE | AC5: CUIABA | AE5: BELEM | AG5: JOAO PESSOA | AI5: RECIFE | AK5: TERESINA | AM5: CURITIBA | AO5: RIO DE JANEIRO | AQ5: NATAL | AS5: PORTO VELHO | AU5: BOA VISTA | AW5: PORTO ALEGRE | AY5: FLORIANOPOLIS | BA5: ARACAJU | BC5: SAO PAULO | BE5: PALMAS
A6: Observação: | B6: %AS (porcentagem Atribuído São Paulo) corresponde a porcentagem do custo total da | D6: Horista | E6: 0.9688 | G6: 1.0013 | I6: 0.9835 | K6: 0.9923 | M6: 1.017 | O6: 0.9971 | Q6: 0.9463 | S6: 1.0222 | U6: 0.9322 | W6: 0.9831 | Y6: 1.0033 | AA6: 0.9956 | AC6: 0.9089 | AE6: 1.0326 | AG6: 1.0206 | AI6: 0.9883 | AK6: 0.9796 | AM6: 1.0025 | AO6: 0.9688 | AQ6: 1.0077 | AS6: 0.9961 | AU6: 0.9885 | AW6: 0.9612 | AY6: 0.9838 | BA6: 0.9588 | BC6: 0.9909 | BE6: 0.9923
B7: composição que foi obtida utilizando preços de insumos de São Paulo por indisponibilidade | D7: Mensalista | E7: 0.5653 | G7: 0.5859 | I7: 0.582 | K7: 0.5746 | M7: 0.6013 | O7: 0.5974 | Q7: 0.5745 | S7: 0.6106 | U7: 0.5747 | W7: 0.5866 | Y7: 0.6106 | AA7: 0.5874 | AC7: 0.5603 | AE7: 0.5998 | AG7: 0.5991 | AI7: 0.581 | AK7: 0.5891 | AM7: 0.5965 | AO7: 0.572 | AQ7: 0.5955 | AS7: 0.5792 | AU7: 0.5772 | AW7: 0.5667 | AY7: 0.5822 | BA7: 0.5718 | BC7: 0.5851 | BE7: 0.592
B8: dos preços de insumos necessários à composição no estado em questão. Custo zerado (hífen)
B9: indica que pelo menos um dos itens da composição não tem custo/preço. | E9: AC | G9: AL | I9: AM | K9: AP | M9: BA | O9: CE | Q9: DF | S9: ES | U9: GO | W9: MA | Y9: MG | AA9: MS | AC9: MT | AE9: PA | AG9: PB | AI9: PE | AK9: PI | AM9: PR | AO9: RJ | AQ9: RN | AS9: RO | AU9: RR | AW9: RS | AY9: SC | BA9: SE | BC9: SP | BE9: TO
A10: Grupo | B10: Código da Composição | C10: Descrição | D10: Unidade | E10: Custo (R$) | F10: %AS | G10: Custo (R$) | H10: %AS | I10: Custo (R$) | J10: %AS | K10: Custo (R$) | L10: %AS | M10: Custo (R$) | N10: %AS | O10: Custo (R$) | P10: %AS | Q10: Custo (R$) | R10: %AS | S10: Custo (R$) | T10: %AS | U10: Custo (R$) | V10: %AS | W10: Custo (R$) | X10: %AS | Y10: Custo (R$) | Z10: %AS | AA10: Custo (R$) | AB10: %AS | AC10: Custo (R$) | AD10: %AS | AE10: Custo (R$) | AF10: %AS | AG10: Custo (R$) | AH10: %AS | AI10: Custo (R$) | AJ10: %AS | AK10: Custo (R$) | AL10: %AS | AM10: Custo (R$) | AN10: %AS | AO10: Custo (R$) | AP10: %AS | AQ10: Custo (R$) | AR10: %AS | AS10: Custo (R$) | AT10: %AS | AU10: Custo (R$) | AV10: %AS | AW10: Custo (R$) | AX10: %AS | AY10: Custo (R$) | AZ10: %AS | BA10: Custo (R$) | BB10: %AS | BC10: Custo (R$) | BD10: %AS | BE10: Custo (R$) | BF10: %AS
A11: Acessibilidade | B11: =HYPERLINK("#"&CELL("address",OFFSET(Analítico!$B$1,MATCH(104658,Analítico!$B:$B,0)-1,3)),104658) -> 0 | C11: PISO PODOTÁTIL DE ALERTA OU DIRECIONAL, DE CONCRETO, ASSENTADO SOBRE ARGAMASSA. AF_03/2024 | D11: M2 | E11: 250.75 | F11: 0 | G11: 154.04 | H11: 0 | I11: 223.07 | J11: 0 | K11: 195.09 | L11: 0 | M11: 166.38 | N11: 0 | O11: 162.24 | P11: 0 | Q11: 186.74 | R11: 0 | S11: 175.63 | T11: 0 | U11: 176.44 | V11: 0 | W11: 161.04 | X11: 0 | Y11: 162.22 | Z11: 0 | AA11: 172.52 | AB11: 0 | AC11: 212.08 | AD11: 0 | AE11: 170.55 | AF11: 0 | AG11: 141.74 | AH11: 0 | AI11: 151.53 | AJ11: 0 | AK11: 146.49 | AL11: 0 | AM11: 156.93 | AN11: 0 | AO11: 178.27 | AP11: 0 | AQ11: 166.23 | AR11: 0 | AS11: 207.56 | AT11: 0 | AU11: 264.17 | AV11: 0 | AW11: 153.18 | AX11: 0 | AY11: 148.07 | AZ11: 0 | BA11: 167.26 | BB11: 0 | BC11: 191.17 | BD11: 0 | BE11: 193.03 | BF11: 0
A112: Argamassas | B112: =HYPERLINK("#"&CELL("address",OFFSET(Analítico!$B$1,MATCH(87398,Analítico!$B:$B,0)-1,3)),87398) -> 0 | C112: ARGAMASSA INDUSTRIALIZADA MULTIUSO PARA REVESTIMENTOS E ASSENTAMENTO DA ALVENARIA, PREPARO MANUAL. AF_08/2019 | D112: M3 | E112: 2968.58 | F112: 0 | G112: 2333.55 | H112: 0 | I112: 2953.05 | J112: 0 | K112: 2573.6 | L112: 0 | M112: 2048.51 | N112: 0 | O112: 2702.33 | P112: 0 | Q112: 1605.25 | R112: 0 | S112: 1841.96 | T112: 0 | U112: 1922.79 | V112: 0 | W112: 2381.81 | X112: 0 | Y112: 1695.47 | Z112: 0 | AA112: 2218.01 | AB112: 0 | AC112: 2866.01 | AD112: 0 | AE112: 2175.25 | AF112: 0 | AG112: 1921.9 | AH112: 0 | AI112: 2349.41 | AJ112: 0 | AK112: 1775.87 | AL112: 0 | AM112: 1944.63 | AN112: 0 | AO112: 1820.52 | AP112: 0 | AQ112: 2328.86 | AR112: 0 | AS112: 2511.05 | AT112: 0 | AU112: 3715.5 | AV112: 0 | AW112: 1939.91 | AX112: 0 | AY112: 1749.38 | AZ112: 0 | BA112: 2181.47 | BB112: 0 | BC112: 2015.95 | BD112: 0 | BE112: 1809.64 | BF112: 0
A1105: Brises | B1105: =HYPERLINK("#"&CELL("address",OFFSET(Analítico!$B$1,MATCH(104943,Analítico!$B:$B,0)-1,3)),104943) -> 0 | C1105: FORNECIMENTO E INSTALAÇÃO DE CONJUNTO DE BRISE EM REQUADRO DE ALUMÍNIO DESLIZANTE, COM PERFIS INTERNOS TUBULARES FIXOS, COM PINTURA ELETROSTÁTICA BRANCA, ACABAMENTO, 150 CM X 265 CM. AF_03/2024 | D1105: M2 | E1105: 0 | G1105: 0 | I1105: 0 | K1105: 0 | M1105: 0 | O1105: 0 | Q1105: 0 | S1105: 0 | U1105: 0 | W1105: 0 | Y1105: 0 | AA1105: 0 | AC1105: 0 | AE1105: 0 | AG1105: 0 | AI1105: 0 | AK1105: 0 | AM1105: 0 | AO1105: 0 | AQ1105: 0 | AS1105: 0 | AU1105: 0 | AW1105: 0 | AY1105: 0 | BA1105: 0 | BC1105: 0 | BE1105: 0
A1493: Custos Horários Produtivo e Improdutivo dos Equipamentos | B1493: =HYPERLINK("#"&CELL("address",OFFSET(Analítico!$B$1,MATCH(102953,Analítico!$B:$B,0)-1,3)),102953) -> 0 | C1493: BETONEIRA CAPACIDADE NOMINAL DE 250 L, CAPACIDADE DE MISTURA DE 175 L, MOTOR ELÉTRICO MONOFÁSICO POTÊNCIA 1CV - CHI DIURNO. AF_05/2023 | D1493: CHI | E1493: 0 | G1493: 0 | I1493: 0 | K1493: 0 | M1493: 0 | O1493: 0 | Q1493: 0 | S1493: 0 | U1493: 0 | W1493: 0 | Y1493: 0 | AA1493: 0 | AC1493: 0 | AE1493: 0 | AG1493: 0 | AI1493: 0 | AK1493: 0 | AM1493: 0 | AO1493: 0 | AQ1493: 0 | AS1493: 0 | AU1493: 0 | AW1493: 0 | AY1493: 0 | BA1493: 0 | BC1493: 0 | BE1493: 0
A1981: Depreciação, Juros, Impostos e Seguros, Manutenção e Materiais na Operação dos Equipamentos | B1981: =HYPERLINK("#"&CELL("address",OFFSET(Analítico!$B$1,MATCH(92715,Analítico!$B:$B,0)-1,3)),92715) -> 0 | C1981: APARELHO PARA CORTE E SOLDA OXI-ACETILENO SOBRE RODAS, INCLUSIVE CILINDROS E MAÇARICOS - MATERIAIS NA OPERAÇÃO. AF_05/2023 | D1981: H | E1981: 114.72 | F1981: 1 | G1981: 139.08 | H1981: 0 | I1981: 114.72 | J1981: 1 | K1981: 114.72 | L1981: 1 | M1981: 164.59 | N1981: 0 | O1981: 105.48 | P1981: 0 | Q1981: 114.72 | R1981: 1 | S1981: 109.52 | T1981: 0 | U1981: 101.96 | V1981: 0 | W1981: 114.72 | X1981: 1 | Y1981: 83.44 | Z1981: 0 | AA1981: 104.3 | AB1981: 0 | AC1981: 124.8 | AD1981: 0 | AE1981: 114.72 | AF1981: 1 | AG1981: 114.72 | AH1981: 1 | AI1981: 114.72 | AJ1981: 1 | AK1981: 114.72 | AL1981: 1 | AM1981: 146.04 | AN1981: 0 | AO1981: 114.72 | AP1981: 1 | AQ1981: 114.72 | AR1981: 1 | AS1981: 114.72 | AT1981: 1 | AU1981: 114.72 | AV1981: 1 | AW1981: 115.24 | AX1981: 0 | AY1981: 114.72 | AZ1981: 1 | BA1981: 114.72 | BB1981: 1 | BC1981: 114.72 | BD1981: 0 | BE1981: 114.72 | BF1981: 1
A1999: Depreciação, Juros, Impostos e Seguros, Manutenção e Materiais na Operação dos Equipamentos | B1999: =HYPERLINK("#"&CELL("address",OFFSET(Analítico!$B$1,MATCH(102948,Analítico!$B:$B,0)-1,3)),102948) -> 0 | C1999: BETONEIRA CAPACIDADE NOMINAL DE 250 L, CAPACIDADE DE MISTURA DE 175 L, MOTOR ELÉTRICO MONOFÁSICO POTÊNCIA 1CV - DEPRECIAÇÃO. AF_05/2023 | D1999: H | E1999: 0 | G1999: 0 | I1999: 0 | K1999: 0 | M1999: 0 | O1999: 0 | Q1999: 0 | S1999: 0 | U1999: 0 | W1999: 0 | Y1999: 0 | AA1999: 0 | AC1999: 0 | AE1999: 0 | AG1999: 0 | AI1999: 0 | AK1999: 0 | AM1999: 0 | AO1999: 0 | AQ1999: 0 | AS1999: 0 | AU1999: 0 | AW1999: 0 | AY1999: 0 | BA1999: 0 | BC1999: 0 | BE1999: 0
A2000: Depreciação, Juros, Impostos e Seguros, Manutenção e Materiais na Operação dos Equipamentos | B2000: =HYPERLINK("#"&CELL("address",OFFSET(Analítico!$B$1,MATCH(102949,Analítico!$B:$B,0)-1,3)),102949) -> 0 | C2000: BETONEIRA CAPACIDADE NOMINAL DE 250 L, CAPACIDADE DE MISTURA DE 175 L, MOTOR ELÉTRICO MONOFÁSICO POTÊNCIA 1CV - JUROS. AF_05/2023 | D2000: H | E2000: 0 | G2000: 0 | I2000: 0 | K2000: 0 | M2000: 0 | O2000: 0 | Q2000: 0 | S2000: 0 | U2000: 0 | W2000: 0 | Y2000: 0 | AA2000: 0 | AC2000: 0 | AE2000: 0 | AG2000: 0 | AI2000: 0 | AK2000: 0 | AM2000: 0 | AO2000: 0 | AQ2000: 0 | AS2000: 0 | AU2000: 0 | AW2000: 0 | AY2000: 0 | BA2000: 0 | BC2000: 0 | BE2000: 0
A7249: Livro SINAPI: Cálculos e Parâmetros | B7249: =HYPERLINK("#"&CELL("address",OFFSET(Analítico!$B$1,MATCH(95371,Analítico!$B:$B,0)-1,3)),95371) -> 0 | C7249: CURSO DE CAPACITAÇÃO PARA PEDREIRO (ENCARGOS COMPLEMENTARES) - HORISTA | D7249: H | E7249: 0.45 | F7249: 0 | G7249: 0.39 | H7249: 0 | I7249: 0.42 | J7249: 0 | K7249: 0.41 | L7249: 0 | M7249: 0.47 | N7249: 0 | O7249: 0.42 | P7249: 0 | Q7249: 0.45 | R7249: 0 | S7249: 0.43 | T7249: 0 | U7249: 0.47 | V7249: 0 | W7249: 0.41 | X7249: 0 | Y7249: 0.5 | Z7249: 0 | AA7249: 0.41 | AB7249: 0 | AC7249: 0.43 | AD7249: 0 | AE7249: 0.43 | AF7249: 0 | AG7249: 0.42 | AH7249: 0 | AI7249: 0.44 | AJ7249: 0 | AK7249: 0.42 | AL7249: 0 | AM7249: 0.56 | AN7249: 0 | AO7249: 0.59 | AP7249: 0 | AQ7249: 0.38 | AR7249: 0 | AS7249: 0.45 | AT7249: 0 | AU7249: 0.5 | AV7249: 0 | AW7249: 0.44 | AX7249: 0 | AY7249: 0.59 | AZ7249: 0 | BA7249: 0.4 | BB7249: 0 | BC7249: 0.51 | BD7249: 0 | BE7249: 0.41 | BF7249: 0
A7260: Livro SINAPI: Cálculos e Parâmetros | B7260: =HYPERLINK("#"&CELL("address",OFFSET(Analítico!$B$1,MATCH(95377,Analítico!$B:$B,0)-1,3)),95377) -> 0 | C7260: CURSO DE CAPACITAÇÃO PARA SERRALHEIRO (ENCARGOS COMPLEMENTARES) - HORISTA | D7260: H | E7260: 0.24 | F7260: 0 | G7260: 0.23 | H7260: 0 | I7260: 0.28 | J7260: 0 | K7260: 0.22 | L7260: 0 | M7260: 0.25 | N7260: 0 | O7260: 0.23 | P7260: 0 | Q7260: 0.24 | R7260: 0 | S7260: 0.27 | T7260: 0 | U7260: 0.25 | V7260: 0 | W7260: 0.22 | X7260: 0 | Y7260: 0.27 | Z7260: 0 | AA7260: 0.23 | AB7260: 0 | AC7260: 0.23 | AD7260: 0 | AE7260: 0.23 | AF7260: 0 | AG7260: 0.23 | AH7260: 0 | AI7260: 0.24 | AJ7260: 0 | AK7260: 0.23 | AL7260: 0 | AM7260: 0.3 | AN7260: 0 | AO7260: 0.32 | AP7260: 0 | AQ7260: 0.21 | AR7260: 0 | AS7260: 0.24 | AT7260: 0 | AU7260: 0.27 | AV7260: 0 | AW7260: 0.24 | AX7260: 0 | AY7260: 0.32 | AZ7260: 0 | BA7260: 0.21 | BB7260: 0 | BC7260: 0.28 | BD7260: 0 | BE7260: 0.22 | BF7260: 0
